import { describe, it, expect, vi } from 'vitest';
import { render, screen } from '@testing-library/react';
import { ErrorBoundary } from './ErrorBoundary';

// Component that throws an error
const ThrowError = ({ shouldThrow }: { shouldThrow: boolean }) => {
  if (shouldThrow) {
    throw new Error('Test error');
  }
  return <div>No error</div>;
};

describe('ErrorBoundary', () => {
  const originalConsoleError = console.error;

  beforeEach(() => {
    console.error = vi.fn();
  });

  afterEach(() => {
    console.error = originalConsoleError;
  });

  it('should render children when there is no error', () => {
    render(
      <ErrorBoundary>
        <ThrowError shouldThrow={false} />
      </ErrorBoundary>
    );
    
    expect(screen.getByText('No error')).toBeInTheDocument();
  });

  it('should render error UI when there is an error', () => {
    render(
      <ErrorBoundary>
        <ThrowError shouldThrow={true} />
      </ErrorBoundary>
    );
    
    expect(screen.getByText('Something went wrong')).toBeInTheDocument();
    expect(screen.getByText('An unexpected error occurred. Please try refreshing the page.')).toBeInTheDocument();
  });

  it('should render custom fallback when provided', () => {
    const customFallback = <div>Custom error message</div>;
    
    render(
      <ErrorBoundary fallback={customFallback}>
        <ThrowError shouldThrow={true} />
      </ErrorBoundary>
    );
    
    expect(screen.getByText('Custom error message')).toBeInTheDocument();
  });
});